2025-03-07 16:26:24.190695 - Error: ('28000', "[28000] [Microsoft][ODBC Driver 17 for SQL Server][SQL Server]Login failed for user 'sa'. (18456) (SQLDriverConnect); [28000] [Microsoft][ODBC Driver 17 for SQL Server]Invalid connection string attribute (0); [28000] [Microsoft][ODBC Driver 17 for SQL Server][SQL Server]Login failed for user 'sa'. (18456); [28000] [Microsoft][ODBC Driver 17 for SQL Server]Invalid connection string attribute (0)")
Function: Tried ODBC: {valid_driver} or failed test_connection
Stack Trace:
Traceback (most recent call last):
  File "main.py", line 466, in test_connection
pyodbc.InterfaceError: ('28000', "[28000] [Microsoft][ODBC Driver 17 for SQL Server][SQL Server]Login failed for user 'sa'. (18456) (SQLDriverConnect); [28000] [Microsoft][ODBC Driver 17 for SQL Server]Invalid connection string attribute (0); [28000] [Microsoft][ODBC Driver 17 for SQL Server][SQL Server]Login failed for user 'sa'. (18456); [28000] [Microsoft][ODBC Driver 17 for SQL Server]Invalid connection string attribute (0)")


2025-03-07 16:26:30.175967 - Error: ('28000', "[28000] [Microsoft][ODBC Driver 17 for SQL Server][SQL Server]Login failed for user 'sa'. (18456) (SQLDriverConnect); [28000] [Microsoft][ODBC Driver 17 for SQL Server]Invalid connection string attribute (0); [28000] [Microsoft][ODBC Driver 17 for SQL Server][SQL Server]Login failed for user 'sa'. (18456); [28000] [Microsoft][ODBC Driver 17 for SQL Server]Invalid connection string attribute (0)")
Function: Tried ODBC: {valid_driver} or failed test_connection
Stack Trace:
Traceback (most recent call last):
  File "main.py", line 466, in test_connection
pyodbc.InterfaceError: ('28000', "[28000] [Microsoft][ODBC Driver 17 for SQL Server][SQL Server]Login failed for user 'sa'. (18456) (SQLDriverConnect); [28000] [Microsoft][ODBC Driver 17 for SQL Server]Invalid connection string attribute (0); [28000] [Microsoft][ODBC Driver 17 for SQL Server][SQL Server]Login failed for user 'sa'. (18456); [28000] [Microsoft][ODBC Driver 17 for SQL Server]Invalid connection string attribute (0)")


2025-03-07 16:28:27.455729 - Error: ('28000', "[28000] [Microsoft][ODBC Driver 17 for SQL Server][SQL Server]Login failed for user 'melih'. (18456) (SQLDriverConnect); [28000] [Microsoft][ODBC Driver 17 for SQL Server]Invalid connection string attribute (0); [28000] [Microsoft][ODBC Driver 17 for SQL Server][SQL Server]Login failed for user 'melih'. (18456); [28000] [Microsoft][ODBC Driver 17 for SQL Server]Invalid connection string attribute (0)")
Function: Tried ODBC: {valid_driver} or failed test_connection
Stack Trace:
Traceback (most recent call last):
  File "main.py", line 466, in test_connection
pyodbc.InterfaceError: ('28000', "[28000] [Microsoft][ODBC Driver 17 for SQL Server][SQL Server]Login failed for user 'melih'. (18456) (SQLDriverConnect); [28000] [Microsoft][ODBC Driver 17 for SQL Server]Invalid connection string attribute (0); [28000] [Microsoft][ODBC Driver 17 for SQL Server][SQL Server]Login failed for user 'melih'. (18456); [28000] [Microsoft][ODBC Driver 17 for SQL Server]Invalid connection string attribute (0)")


2025-03-07 16:29:26.661559 - Error: ('28000', "[28000] [Microsoft][ODBC Driver 17 for SQL Server][SQL Server]Login failed for user 'melih'. (18456) (SQLDriverConnect); [28000] [Microsoft][ODBC Driver 17 for SQL Server]Invalid connection string attribute (0); [28000] [Microsoft][ODBC Driver 17 for SQL Server][SQL Server]Login failed for user 'melih'. (18456); [28000] [Microsoft][ODBC Driver 17 for SQL Server]Invalid connection string attribute (0)")
Function: Tried ODBC: {valid_driver} or failed test_connection
Stack Trace:
Traceback (most recent call last):
  File "main.py", line 466, in test_connection
pyodbc.InterfaceError: ('28000', "[28000] [Microsoft][ODBC Driver 17 for SQL Server][SQL Server]Login failed for user 'melih'. (18456) (SQLDriverConnect); [28000] [Microsoft][ODBC Driver 17 for SQL Server]Invalid connection string attribute (0); [28000] [Microsoft][ODBC Driver 17 for SQL Server][SQL Server]Login failed for user 'melih'. (18456); [28000] [Microsoft][ODBC Driver 17 for SQL Server]Invalid connection string attribute (0)")


2025-03-07 16:29:32.107991 - Error: ('28000', "[28000] [Microsoft][ODBC Driver 17 for SQL Server][SQL Server]Login failed for user 'melih'. (18456) (SQLDriverConnect); [28000] [Microsoft][ODBC Driver 17 for SQL Server]Invalid connection string attribute (0); [28000] [Microsoft][ODBC Driver 17 for SQL Server][SQL Server]Login failed for user 'melih'. (18456); [28000] [Microsoft][ODBC Driver 17 for SQL Server]Invalid connection string attribute (0)")
Function: Tried ODBC: {valid_driver} or failed test_connection
Stack Trace:
Traceback (most recent call last):
  File "main.py", line 466, in test_connection
pyodbc.InterfaceError: ('28000', "[28000] [Microsoft][ODBC Driver 17 for SQL Server][SQL Server]Login failed for user 'melih'. (18456) (SQLDriverConnect); [28000] [Microsoft][ODBC Driver 17 for SQL Server]Invalid connection string attribute (0); [28000] [Microsoft][ODBC Driver 17 for SQL Server][SQL Server]Login failed for user 'melih'. (18456); [28000] [Microsoft][ODBC Driver 17 for SQL Server]Invalid connection string attribute (0)")


2025-03-07 18:35:51.048671 - Error: Can only use .str accessor with string values!
Function: CheckDB
Stack Trace:
Traceback (most recent call last):
  File "main.py", line 794, in generate_dataframe_from_excel
  File "pandas\core\generic.py", line 6299, in __getattr__
  File "pandas\core\accessor.py", line 224, in __get__
  File "pandas\core\strings\accessor.py", line 191, in __init__
  File "pandas\core\strings\accessor.py", line 245, in _validate
AttributeError: Can only use .str accessor with string values!


2025-03-07 18:35:51.089999 - Error: local variable 'tag' referenced before assignment
Function: CompatibilityLevel
Stack Trace:
Traceback (most recent call last):
  File "main.py", line 1183, in generate_dataframe_from_excel
UnboundLocalError: local variable 'tag' referenced before assignment


2025-03-07 18:40:04.218174 - Error: ('28000', "[28000] [Microsoft][ODBC Driver 17 for SQL Server][SQL Server]Login failed for user 'melih'. (18456) (SQLDriverConnect); [28000] [Microsoft][ODBC Driver 17 for SQL Server]Invalid connection string attribute (0); [28000] [Microsoft][ODBC Driver 17 for SQL Server][SQL Server]Login failed for user 'melih'. (18456); [28000] [Microsoft][ODBC Driver 17 for SQL Server]Invalid connection string attribute (0)")
Function: Tried ODBC: {valid_driver} or failed test_connection
Stack Trace:
Traceback (most recent call last):
  File "main.py", line 466, in test_connection
pyodbc.InterfaceError: ('28000', "[28000] [Microsoft][ODBC Driver 17 for SQL Server][SQL Server]Login failed for user 'melih'. (18456) (SQLDriverConnect); [28000] [Microsoft][ODBC Driver 17 for SQL Server]Invalid connection string attribute (0); [28000] [Microsoft][ODBC Driver 17 for SQL Server][SQL Server]Login failed for user 'melih'. (18456); [28000] [Microsoft][ODBC Driver 17 for SQL Server]Invalid connection string attribute (0)")


2025-03-10 16:10:48.457439 - Error: ('42000', "[42000] [Microsoft][ODBC Driver 17 for SQL Server][SQL Server]User 'guest' does not have permission to run DBCC LOGINFO. (2571) (SQLExecDirectW)")
Function: SQL Execution Error
Stack Trace:
Traceback (most recent call last):
  File "main.py", line 2240, in run_scripts_and_export
pyodbc.ProgrammingError: ('42000', "[42000] [Microsoft][ODBC Driver 17 for SQL Server][SQL Server]User 'guest' does not have permission to run DBCC LOGINFO. (2571) (SQLExecDirectW)")


2025-03-10 16:10:48.815396 - Error: ('42000', "[42000] [Microsoft][ODBC Driver 17 for SQL Server][SQL Server]User 'guest' does not have permission to run DBCC dbinfo. (2571) (SQLExecDirectW)")
Function: SQL Execution Error
Stack Trace:
Traceback (most recent call last):
  File "main.py", line 2240, in run_scripts_and_export
pyodbc.ProgrammingError: ('42000', "[42000] [Microsoft][ODBC Driver 17 for SQL Server][SQL Server]User 'guest' does not have permission to run DBCC dbinfo. (2571) (SQLExecDirectW)")


2025-03-10 16:10:49.300192 - Error: ('42000', "[42000] [Microsoft][ODBC Driver 17 for SQL Server][SQL Server]VIEW SERVER PERFORMANCE STATE permission was denied on object 'server', database 'master'. (300) (SQLExecDirectW); [42000] [Microsoft][ODBC Driver 17 for SQL Server][SQL Server]The user does not have permission to perform this action. (297)")
Function: SQL Execution Error
Stack Trace:
Traceback (most recent call last):
  File "main.py", line 2240, in run_scripts_and_export
pyodbc.ProgrammingError: ('42000', "[42000] [Microsoft][ODBC Driver 17 for SQL Server][SQL Server]VIEW SERVER PERFORMANCE STATE permission was denied on object 'server', database 'master'. (300) (SQLExecDirectW); [42000] [Microsoft][ODBC Driver 17 for SQL Server][SQL Server]The user does not have permission to perform this action. (297)")


2025-03-10 16:10:49.921615 - Error: ('42S02', "[42S02] [Microsoft][ODBC Driver 17 for SQL Server][SQL Server]Invalid object name '#ServerConfiguration'. (208) (SQLExecDirectW)")
Function: windows_group_error
Stack Trace:
Traceback (most recent call last):
  File "main.py", line 2255, in run_scripts_and_export
pyodbc.ProgrammingError: ('42S02', "[42S02] [Microsoft][ODBC Driver 17 for SQL Server][SQL Server]Invalid object name '#ServerConfiguration'. (208) (SQLExecDirectW)")


2025-03-10 16:10:49.924142 - Error: ('42S02', "[42S02] [Microsoft][ODBC Driver 17 for SQL Server][SQL Server]Invalid object name '#TotalMemory'. (208) (SQLExecDirectW)")
Function: windows_group_error
Stack Trace:
Traceback (most recent call last):
  File "main.py", line 2255, in run_scripts_and_export
pyodbc.ProgrammingError: ('42S02', "[42S02] [Microsoft][ODBC Driver 17 for SQL Server][SQL Server]Invalid object name '#TotalMemory'. (208) (SQLExecDirectW)")


2025-03-10 16:10:49.926257 - Error: ('42S02', "[42S02] [Microsoft][ODBC Driver 17 for SQL Server][SQL Server]Invalid object name '#MinServerMemory'. (208) (SQLExecDirectW)")
Function: windows_group_error
Stack Trace:
Traceback (most recent call last):
  File "main.py", line 2255, in run_scripts_and_export
pyodbc.ProgrammingError: ('42S02', "[42S02] [Microsoft][ODBC Driver 17 for SQL Server][SQL Server]Invalid object name '#MinServerMemory'. (208) (SQLExecDirectW)")


2025-03-10 16:10:49.927269 - Error: ('42S02', "[42S02] [Microsoft][ODBC Driver 17 for SQL Server][SQL Server]Invalid object name '#MaxServerMemory'. (208) (SQLExecDirectW)")
Function: windows_group_error
Stack Trace:
Traceback (most recent call last):
  File "main.py", line 2255, in run_scripts_and_export
pyodbc.ProgrammingError: ('42S02', "[42S02] [Microsoft][ODBC Driver 17 for SQL Server][SQL Server]Invalid object name '#MaxServerMemory'. (208) (SQLExecDirectW)")


2025-03-10 16:10:49.930289 - Error: ('42S02', "[42S02] [Microsoft][ODBC Driver 17 for SQL Server][SQL Server]Invalid object name '#BackupCompressionInfo'. (208) (SQLExecDirectW)")
Function: windows_group_error
Stack Trace:
Traceback (most recent call last):
  File "main.py", line 2255, in run_scripts_and_export
pyodbc.ProgrammingError: ('42S02', "[42S02] [Microsoft][ODBC Driver 17 for SQL Server][SQL Server]Invalid object name '#BackupCompressionInfo'. (208) (SQLExecDirectW)")


2025-03-10 16:10:49.932928 - Error: ('42S02', "[42S02] [Microsoft][ODBC Driver 17 for SQL Server][SQL Server]Invalid object name '#DatabaseCPUUsage'. (208) (SQLExecDirectW)")
Function: windows_group_error
Stack Trace:
Traceback (most recent call last):
  File "main.py", line 2255, in run_scripts_and_export
pyodbc.ProgrammingError: ('42S02', "[42S02] [Microsoft][ODBC Driver 17 for SQL Server][SQL Server]Invalid object name '#DatabaseCPUUsage'. (208) (SQLExecDirectW)")


2025-03-10 16:10:49.933988 - Error: ('42S02', "[42S02] [Microsoft][ODBC Driver 17 for SQL Server][SQL Server]Invalid object name '#DatabaseFileInfo'. (208) (SQLExecDirectW)")
Function: windows_group_error
Stack Trace:
Traceback (most recent call last):
  File "main.py", line 2255, in run_scripts_and_export
pyodbc.ProgrammingError: ('42S02', "[42S02] [Microsoft][ODBC Driver 17 for SQL Server][SQL Server]Invalid object name '#DatabaseFileInfo'. (208) (SQLExecDirectW)")


2025-03-10 16:10:49.935998 - Error: ('42S02', "[42S02] [Microsoft][ODBC Driver 17 for SQL Server][SQL Server]Invalid object name '#BackupDetails'. (208) (SQLExecDirectW)")
Function: windows_group_error
Stack Trace:
Traceback (most recent call last):
  File "main.py", line 2255, in run_scripts_and_export
pyodbc.ProgrammingError: ('42S02', "[42S02] [Microsoft][ODBC Driver 17 for SQL Server][SQL Server]Invalid object name '#BackupDetails'. (208) (SQLExecDirectW)")


2025-03-10 16:10:49.938002 - Error: ('42S02', "[42S02] [Microsoft][ODBC Driver 17 for SQL Server][SQL Server]Invalid object name '#DatabaseSizeInfo'. (208) (SQLExecDirectW)")
Function: windows_group_error
Stack Trace:
Traceback (most recent call last):
  File "main.py", line 2255, in run_scripts_and_export
pyodbc.ProgrammingError: ('42S02', "[42S02] [Microsoft][ODBC Driver 17 for SQL Server][SQL Server]Invalid object name '#DatabaseSizeInfo'. (208) (SQLExecDirectW)")


2025-03-10 16:10:49.939197 - Error: ('42S02', "[42S02] [Microsoft][ODBC Driver 17 for SQL Server][SQL Server]Invalid object name '#BackupStats'. (208) (SQLExecDirectW)")
Function: windows_group_error
Stack Trace:
Traceback (most recent call last):
  File "main.py", line 2255, in run_scripts_and_export
pyodbc.ProgrammingError: ('42S02', "[42S02] [Microsoft][ODBC Driver 17 for SQL Server][SQL Server]Invalid object name '#BackupStats'. (208) (SQLExecDirectW)")


2025-03-10 16:10:49.940194 - Error: ('42S02', "[42S02] [Microsoft][ODBC Driver 17 for SQL Server][SQL Server]Invalid object name '#DeadlockPerformance'. (208) (SQLExecDirectW)")
Function: windows_group_error
Stack Trace:
Traceback (most recent call last):
  File "main.py", line 2255, in run_scripts_and_export
pyodbc.ProgrammingError: ('42S02', "[42S02] [Microsoft][ODBC Driver 17 for SQL Server][SQL Server]Invalid object name '#DeadlockPerformance'. (208) (SQLExecDirectW)")


2025-03-10 16:10:49.942706 - Error: ('42S02', "[42S02] [Microsoft][ODBC Driver 17 for SQL Server][SQL Server]Invalid object name '#DatabasePageVerifyInfo'. (208) (SQLExecDirectW)")
Function: windows_group_error
Stack Trace:
Traceback (most recent call last):
  File "main.py", line 2255, in run_scripts_and_export
pyodbc.ProgrammingError: ('42S02', "[42S02] [Microsoft][ODBC Driver 17 for SQL Server][SQL Server]Invalid object name '#DatabasePageVerifyInfo'. (208) (SQLExecDirectW)")


2025-03-10 16:10:49.943703 - Error: ('42S02', "[42S02] [Microsoft][ODBC Driver 17 for SQL Server][SQL Server]Invalid object name '#DatabaseCompatibilityInfo'. (208) (SQLExecDirectW)")
Function: windows_group_error
Stack Trace:
Traceback (most recent call last):
  File "main.py", line 2255, in run_scripts_and_export
pyodbc.ProgrammingError: ('42S02', "[42S02] [Microsoft][ODBC Driver 17 for SQL Server][SQL Server]Invalid object name '#DatabaseCompatibilityInfo'. (208) (SQLExecDirectW)")


2025-03-10 16:10:49.945698 - Error: ('42S02', "[42S02] [Microsoft][ODBC Driver 17 for SQL Server][SQL Server]Invalid object name '#DatabaseAutoShrinkInfo'. (208) (SQLExecDirectW)")
Function: windows_group_error
Stack Trace:
Traceback (most recent call last):
  File "main.py", line 2255, in run_scripts_and_export
pyodbc.ProgrammingError: ('42S02', "[42S02] [Microsoft][ODBC Driver 17 for SQL Server][SQL Server]Invalid object name '#DatabaseAutoShrinkInfo'. (208) (SQLExecDirectW)")


2025-03-10 16:10:49.948203 - Error: ('42S02', "[42S02] [Microsoft][ODBC Driver 17 for SQL Server][SQL Server]Invalid object name '#DatabaseAutoCloseInfo'. (208) (SQLExecDirectW)")
Function: windows_group_error
Stack Trace:
Traceback (most recent call last):
  File "main.py", line 2255, in run_scripts_and_export
pyodbc.ProgrammingError: ('42S02', "[42S02] [Microsoft][ODBC Driver 17 for SQL Server][SQL Server]Invalid object name '#DatabaseAutoCloseInfo'. (208) (SQLExecDirectW)")


2025-03-10 16:10:49.950219 - Error: ('42S02', "[42S02] [Microsoft][ODBC Driver 17 for SQL Server][SQL Server]Invalid object name '#DatabaseLogInfo'. (208) (SQLExecDirectW)")
Function: windows_group_error
Stack Trace:
Traceback (most recent call last):
  File "main.py", line 2255, in run_scripts_and_export
pyodbc.ProgrammingError: ('42S02', "[42S02] [Microsoft][ODBC Driver 17 for SQL Server][SQL Server]Invalid object name '#DatabaseLogInfo'. (208) (SQLExecDirectW)")


2025-03-10 16:10:49.951728 - Error: ('42S02', "[42S02] [Microsoft][ODBC Driver 17 for SQL Server][SQL Server]Invalid object name '#JobHistory'. (208) (SQLExecDirectW)")
Function: windows_group_error
Stack Trace:
Traceback (most recent call last):
  File "main.py", line 2255, in run_scripts_and_export
pyodbc.ProgrammingError: ('42S02', "[42S02] [Microsoft][ODBC Driver 17 for SQL Server][SQL Server]Invalid object name '#JobHistory'. (208) (SQLExecDirectW)")


2025-03-10 16:10:49.953729 - Error: ('42S02', "[42S02] [Microsoft][ODBC Driver 17 for SQL Server][SQL Server]Invalid object name '#ORPHANUSER'. (208) (SQLExecDirectW)")
Function: windows_group_error
Stack Trace:
Traceback (most recent call last):
  File "main.py", line 2255, in run_scripts_and_export
pyodbc.ProgrammingError: ('42S02', "[42S02] [Microsoft][ODBC Driver 17 for SQL Server][SQL Server]Invalid object name '#ORPHANUSER'. (208) (SQLExecDirectW)")


2025-03-10 16:10:49.955845 - Error: ('42S02', "[42S02] [Microsoft][ODBC Driver 17 for SQL Server][SQL Server]Invalid object name '#EmptyPasswordLogins'. (208) (SQLExecDirectW)")
Function: windows_group_error
Stack Trace:
Traceback (most recent call last):
  File "main.py", line 2255, in run_scripts_and_export
pyodbc.ProgrammingError: ('42S02', "[42S02] [Microsoft][ODBC Driver 17 for SQL Server][SQL Server]Invalid object name '#EmptyPasswordLogins'. (208) (SQLExecDirectW)")


2025-03-10 16:10:49.956873 - Error: ('42S02', "[42S02] [Microsoft][ODBC Driver 17 for SQL Server][SQL Server]Invalid object name '#ServerLogins'. (208) (SQLExecDirectW)")
Function: windows_group_error
Stack Trace:
Traceback (most recent call last):
  File "main.py", line 2255, in run_scripts_and_export
pyodbc.ProgrammingError: ('42S02', "[42S02] [Microsoft][ODBC Driver 17 for SQL Server][SQL Server]Invalid object name '#ServerLogins'. (208) (SQLExecDirectW)")


2025-03-10 16:10:51.083184 - Error: ('42000', "[42000] [Microsoft][ODBC Driver 17 for SQL Server][SQL Server]VIEW SERVER PERFORMANCE STATE permission was denied on object 'server', database 'master'. (300) (SQLExecDirectW); [42000] [Microsoft][ODBC Driver 17 for SQL Server][SQL Server]The user does not have permission to perform this action. (297)")
Function: SQL Execution Error
Stack Trace:
Traceback (most recent call last):
  File "main.py", line 2240, in run_scripts_and_export
pyodbc.ProgrammingError: ('42000', "[42000] [Microsoft][ODBC Driver 17 for SQL Server][SQL Server]VIEW SERVER PERFORMANCE STATE permission was denied on object 'server', database 'master'. (300) (SQLExecDirectW); [42000] [Microsoft][ODBC Driver 17 for SQL Server][SQL Server]The user does not have permission to perform this action. (297)")


2025-03-10 16:10:51.084319 - Error: ('42S02', "[42S02] [Microsoft][ODBC Driver 17 for SQL Server][SQL Server]Invalid object name '#MissingIndexCount'. (208) (SQLExecDirectW)")
Function: windows_group_error
Stack Trace:
Traceback (most recent call last):
  File "main.py", line 2255, in run_scripts_and_export
pyodbc.ProgrammingError: ('42S02', "[42S02] [Microsoft][ODBC Driver 17 for SQL Server][SQL Server]Invalid object name '#MissingIndexCount'. (208) (SQLExecDirectW)")


2025-03-10 16:10:51.085324 - Error: ('42S02', "[42S02] [Microsoft][ODBC Driver 17 for SQL Server][SQL Server]Invalid object name '#ClusteredIndexes'. (208) (SQLExecDirectW)")
Function: windows_group_error
Stack Trace:
Traceback (most recent call last):
  File "main.py", line 2255, in run_scripts_and_export
pyodbc.ProgrammingError: ('42S02', "[42S02] [Microsoft][ODBC Driver 17 for SQL Server][SQL Server]Invalid object name '#ClusteredIndexes'. (208) (SQLExecDirectW)")


2025-03-10 16:10:51.086789 - Error: ('42S02', "[42S02] [Microsoft][ODBC Driver 17 for SQL Server][SQL Server]Invalid object name '#SQLServerBrowser'. (208) (SQLExecDirectW)")
Function: windows_group_error
Stack Trace:
Traceback (most recent call last):
  File "main.py", line 2255, in run_scripts_and_export
pyodbc.ProgrammingError: ('42S02', "[42S02] [Microsoft][ODBC Driver 17 for SQL Server][SQL Server]Invalid object name '#SQLServerBrowser'. (208) (SQLExecDirectW)")


2025-03-10 16:10:53.248302 - Error: ('42S02', "[42S02] [Microsoft][ODBC Driver 17 for SQL Server][SQL Server]Invalid object name '#LeftoverFakeIndex'. (208) (SQLExecDirectW)")
Function: windows_group_error
Stack Trace:
Traceback (most recent call last):
  File "main.py", line 2255, in run_scripts_and_export
pyodbc.ProgrammingError: ('42S02', "[42S02] [Microsoft][ODBC Driver 17 for SQL Server][SQL Server]Invalid object name '#LeftoverFakeIndex'. (208) (SQLExecDirectW)")


2025-03-10 16:10:53.249471 - Error: ('42S02', "[42S02] [Microsoft][ODBC Driver 17 for SQL Server][SQL Server]Invalid object name '#UpdateStats'. (208) (SQLExecDirectW)")
Function: windows_group_error
Stack Trace:
Traceback (most recent call last):
  File "main.py", line 2255, in run_scripts_and_export
pyodbc.ProgrammingError: ('42S02', "[42S02] [Microsoft][ODBC Driver 17 for SQL Server][SQL Server]Invalid object name '#UpdateStats'. (208) (SQLExecDirectW)")


2025-03-10 16:10:53.586224 - Error: ('42000', '[42000] [Microsoft][ODBC Driver 17 for SQL Server][SQL Server]User does not have permission to perform this action. (15247) (SQLExecDirectW)')
Function: SQL Execution Error
Stack Trace:
Traceback (most recent call last):
  File "main.py", line 2240, in run_scripts_and_export
pyodbc.ProgrammingError: ('42000', '[42000] [Microsoft][ODBC Driver 17 for SQL Server][SQL Server]User does not have permission to perform this action. (15247) (SQLExecDirectW)')


2025-03-10 16:10:54.205508 - Error: ('42S02', "[42S02] [Microsoft][ODBC Driver 17 for SQL Server][SQL Server]Cannot drop the table '#ServerConfiguration', because it does not exist or you do not have permission. (3701) (SQLExecDirectW)")
Function: SQL Execution Error
Stack Trace:
Traceback (most recent call last):
  File "main.py", line 2240, in run_scripts_and_export
pyodbc.ProgrammingError: ('42S02', "[42S02] [Microsoft][ODBC Driver 17 for SQL Server][SQL Server]Cannot drop the table '#ServerConfiguration', because it does not exist or you do not have permission. (3701) (SQLExecDirectW)")


2025-03-10 16:10:56.276215 - Error: single positional indexer is out-of-bounds
Function: generate_dataframe_from_excel
Stack Trace:
Traceback (most recent call last):
  File "main.py", line 561, in generate_dataframe_from_excel
  File "pandas\core\indexing.py", line 1191, in __getitem__
  File "pandas\core\indexing.py", line 1752, in _getitem_axis
  File "pandas\core\indexing.py", line 1685, in _validate_integer
IndexError: single positional indexer is out-of-bounds


2025-03-10 16:10:57.804346 - Error: 'NoneType' object is not subscriptable
Function: group_dataframe
Stack Trace:
Traceback (most recent call last):
  File "main.py", line 1616, in group_dataframe
TypeError: 'NoneType' object is not subscriptable


2025-03-10 16:10:57.804346 - Error: 'NoneType' object is not subscriptable
Function: summarize_dataframe
Stack Trace:
Traceback (most recent call last):
  File "main.py", line 1576, in summarize_dataframe
TypeError: 'NoneType' object is not subscriptable


2025-03-10 16:10:57.805362 - Error: 'NoneType' object has no attribute 'merge'
Function: score_table
Stack Trace:
Traceback (most recent call last):
  File "main.py", line 536, in score_table
AttributeError: 'NoneType' object has no attribute 'merge'


2025-03-10 16:10:57.903413 - Error: 'NoneType' object has no attribute 'to_excel'
Function: excel_writer
Stack Trace:
Traceback (most recent call last):
  File "main.py", line 1838, in generate_pdf_report
AttributeError: 'NoneType' object has no attribute 'to_excel'


2025-03-10 16:10:57.904448 - Error: critical(parent: Optional[QWidget], title: Optional[str], text: Optional[str], buttons: Union[QMessageBox.StandardButtons, QMessageBox.StandardButton] = QMessageBox.Ok, defaultButton: QMessageBox.StandardButton = QMessageBox.NoButton): argument 1 has unexpected type 'str'
Function: run_script
Stack Trace:
Traceback (most recent call last):
  File "main.py", line 1838, in generate_pdf_report
AttributeError: 'NoneType' object has no attribute 'to_excel'

During handling of the above exception, another exception occurred:

Traceback (most recent call last):
  File "main.py", line 2295, in run_scripts_and_export
  File "main.py", line 1841, in generate_pdf_report
TypeError: critical(parent: Optional[QWidget], title: Optional[str], text: Optional[str], buttons: Union[QMessageBox.StandardButtons, QMessageBox.StandardButton] = QMessageBox.Ok, defaultButton: QMessageBox.StandardButton = QMessageBox.NoButton): argument 1 has unexpected type 'str'


