2025-08-19 16:25:24.652479 - Error: ('08001', '[08001] [Microsoft][ODBC Driver 17 for SQL Server]Named Pipes Provider: Could not open a connection to SQL Server [53].  (53) (SQLDriverConnect); [08001] [Microsoft][ODBC Driver 17 for SQL Server]Login timeout expired (0); [08001] [Microsoft][ODBC Driver 17 for SQL Server]Invalid connection string attribute (0); [08001] [Microsoft][ODBC Driver 17 for SQL Server]A network-related or instance-specific error has occurred while establishing a connection to SQL Server. Server is not found or not accessible. Check if instance name is correct and if SQL Server is configured to allow remote connections. For more information see SQL Server Books Online. (53)')
Function: Tried ODBC: {valid_driver} or failed test_connection
Stack Trace:
Traceback (most recent call last):
  File "C:\Users\ravel\OneDrive\Desktop\zip\home\vlhn\dev\new\health-check-poc\health-check-v12.py", line 1270, in test_connection
    self.connection = pyodbc.connect(self.conn_str, autocommit=True)
                      ~~~~~~~~~~~~~~^^^^^^^^^^^^^^^^^^^^^^^^^^^^^^^^
pyodbc.OperationalError: ('08001', '[08001] [Microsoft][ODBC Driver 17 for SQL Server]Named Pipes Provider: Could not open a connection to SQL Server [53].  (53) (SQLDriverConnect); [08001] [Microsoft][ODBC Driver 17 for SQL Server]Login timeout expired (0); [08001] [Microsoft][ODBC Driver 17 for SQL Server]Invalid connection string attribute (0); [08001] [Microsoft][ODBC Driver 17 for SQL Server]A network-related or instance-specific error has occurred while establishing a connection to SQL Server. Server is not found or not accessible. Check if instance name is correct and if SQL Server is configured to allow remote connections. For more information see SQL Server Books Online. (53)')


2025-08-19 16:25:31.827613 - Error: [Errno 2] No such file or directory: 'C:\\Users\\ravel\\OneDrive\\Desktop\\zip\\home\\vlhn\\dev\\new\\health-check-poc\\serverinfo.txt'
Function: execute_serverinfo_statements
Stack Trace:
Traceback (most recent call last):
  File "C:\Users\ravel\OneDrive\Desktop\zip\home\vlhn\dev\new\health-check-poc\health-check-v12.py", line 1284, in test_connection
    with open(file_path, "r", encoding="utf-8") as f:
         ~~~~^^^^^^^^^^^^^^^^^^^^^^^^^^^^^^^^^^
FileNotFoundError: [Errno 2] No such file or directory: 'C:\\Users\\ravel\\OneDrive\\Desktop\\zip\\home\\vlhn\\dev\\new\\health-check-poc\\serverinfo.txt'


2025-08-19 16:26:03.510029 - Error: cannot access local variable 'tag' where it is not associated with a value
Function: CompatibilityLevel
Stack Trace:
Traceback (most recent call last):
  File "C:\Users\ravel\OneDrive\Desktop\zip\home\vlhn\dev\new\health-check-poc\health-check-v12.py", line 2068, in generate_dataframe_from_excel
    status = 0 if tag == 'Failed' else (2 if tag == 'Warning' else 1)
                  ^^^
UnboundLocalError: cannot access local variable 'tag' where it is not associated with a value


2025-08-19 16:26:03.550284 - Error: 'PageCount'
Function: ReIndex
Stack Trace:
Traceback (most recent call last):
  File "C:\Users\ravel\OneDrive\Desktop\zip\home\vlhn\dev\new\health-check-poc\venv\Lib\site-packages\pandas\core\indexes\base.py", line 3812, in get_loc
    return self._engine.get_loc(casted_key)
           ~~~~~~~~~~~~~~~~~~~~^^^^^^^^^^^^
  File "pandas/_libs/index.pyx", line 167, in pandas._libs.index.IndexEngine.get_loc
  File "pandas/_libs/index.pyx", line 196, in pandas._libs.index.IndexEngine.get_loc
  File "pandas/_libs/hashtable_class_helper.pxi", line 7088, in pandas._libs.hashtable.PyObjectHashTable.get_item
  File "pandas/_libs/hashtable_class_helper.pxi", line 7096, in pandas._libs.hashtable.PyObjectHashTable.get_item
KeyError: 'PageCount'

The above exception was the direct cause of the following exception:

Traceback (most recent call last):
  File "C:\Users\ravel\OneDrive\Desktop\zip\home\vlhn\dev\new\health-check-poc\health-check-v12.py", line 1552, in generate_dataframe_from_excel
    sheet_df["PageCount"] = pd.to_numeric(sheet_df["PageCount"], errors="coerce").fillna(0)
                                          ~~~~~~~~^^^^^^^^^^^^^
  File "C:\Users\ravel\OneDrive\Desktop\zip\home\vlhn\dev\new\health-check-poc\venv\Lib\site-packages\pandas\core\frame.py", line 4107, in __getitem__
    indexer = self.columns.get_loc(key)
  File "C:\Users\ravel\OneDrive\Desktop\zip\home\vlhn\dev\new\health-check-poc\venv\Lib\site-packages\pandas\core\indexes\base.py", line 3819, in get_loc
    raise KeyError(key) from err
KeyError: 'PageCount'


2025-08-19 16:26:03.557724 - Error: 'TotalPages'
Function: UpdateStats
Stack Trace:
Traceback (most recent call last):
  File "C:\Users\ravel\OneDrive\Desktop\zip\home\vlhn\dev\new\health-check-poc\venv\Lib\site-packages\pandas\core\indexes\base.py", line 3812, in get_loc
    return self._engine.get_loc(casted_key)
           ~~~~~~~~~~~~~~~~~~~~^^^^^^^^^^^^
  File "pandas/_libs/index.pyx", line 167, in pandas._libs.index.IndexEngine.get_loc
  File "pandas/_libs/index.pyx", line 196, in pandas._libs.index.IndexEngine.get_loc
  File "pandas/_libs/hashtable_class_helper.pxi", line 7088, in pandas._libs.hashtable.PyObjectHashTable.get_item
  File "pandas/_libs/hashtable_class_helper.pxi", line 7096, in pandas._libs.hashtable.PyObjectHashTable.get_item
KeyError: 'TotalPages'

The above exception was the direct cause of the following exception:

Traceback (most recent call last):
  File "C:\Users\ravel\OneDrive\Desktop\zip\home\vlhn\dev\new\health-check-poc\health-check-v12.py", line 1520, in generate_dataframe_from_excel
    sheet_df["TotalPages"] = pd.to_numeric(sheet_df["TotalPages"], errors='coerce').fillna(0)
                                           ~~~~~~~~^^^^^^^^^^^^^^
  File "C:\Users\ravel\OneDrive\Desktop\zip\home\vlhn\dev\new\health-check-poc\venv\Lib\site-packages\pandas\core\frame.py", line 4107, in __getitem__
    indexer = self.columns.get_loc(key)
  File "C:\Users\ravel\OneDrive\Desktop\zip\home\vlhn\dev\new\health-check-poc\venv\Lib\site-packages\pandas\core\indexes\base.py", line 3819, in get_loc
    raise KeyError(key) from err
KeyError: 'TotalPages'


