2025-08-29 10:05:11.955339 - Error: ('28000', "[28000] [Microsoft][ODBC Driver 17 for SQL Server][SQL Server]Login failed for user 'admn0'. (18456) (SQLDriverConnect); [28000] [Microsoft][ODBC Driver 17 for SQL Server]Invalid connection string attribute (0); [28000] [Microsoft][ODBC Driver 17 for SQL Server][SQL Server]Login failed for user 'admn0'. (18456); [28000] [Microsoft][ODBC Driver 17 for SQL Server]Invalid connection string attribute (0)")
Function: Tried ODBC: {valid_driver} or failed test_connection
Stack Trace:
Traceback (most recent call last):
  File "C:\Users\ravel\OneDrive\Desktop\health-check-poc-2\health-check-poc\health-check-v12.py", line 1236, in test_connection
    self.connection = pyodbc.connect(self.conn_str, autocommit=True)
                      ~~~~~~~~~~~~~~^^^^^^^^^^^^^^^^^^^^^^^^^^^^^^^^
pyodbc.InterfaceError: ('28000', "[28000] [Microsoft][ODBC Driver 17 for SQL Server][SQL Server]Login failed for user 'admn0'. (18456) (SQLDriverConnect); [28000] [Microsoft][ODBC Driver 17 for SQL Server]Invalid connection string attribute (0); [28000] [Microsoft][ODBC Driver 17 for SQL Server][SQL Server]Login failed for user 'admn0'. (18456); [28000] [Microsoft][ODBC Driver 17 for SQL Server]Invalid connection string attribute (0)")


2025-08-29 10:05:21.606040 - Error: ('28000', "[28000] [Microsoft][ODBC Driver 17 for SQL Server][SQL Server]Login failed for user 'admn0'. (18456) (SQLDriverConnect); [28000] [Microsoft][ODBC Driver 17 for SQL Server]Invalid connection string attribute (0); [28000] [Microsoft][ODBC Driver 17 for SQL Server][SQL Server]Login failed for user 'admn0'. (18456); [28000] [Microsoft][ODBC Driver 17 for SQL Server]Invalid connection string attribute (0)")
Function: Tried ODBC: {valid_driver} or failed test_connection
Stack Trace:
Traceback (most recent call last):
  File "C:\Users\ravel\OneDrive\Desktop\health-check-poc-2\health-check-poc\health-check-v12.py", line 1236, in test_connection
    self.connection = pyodbc.connect(self.conn_str, autocommit=True)
                      ~~~~~~~~~~~~~~^^^^^^^^^^^^^^^^^^^^^^^^^^^^^^^^
pyodbc.InterfaceError: ('28000', "[28000] [Microsoft][ODBC Driver 17 for SQL Server][SQL Server]Login failed for user 'admn0'. (18456) (SQLDriverConnect); [28000] [Microsoft][ODBC Driver 17 for SQL Server]Invalid connection string attribute (0); [28000] [Microsoft][ODBC Driver 17 for SQL Server][SQL Server]Login failed for user 'admn0'. (18456); [28000] [Microsoft][ODBC Driver 17 for SQL Server]Invalid connection string attribute (0)")


2025-08-29 10:06:44.511660 - Error: 'CLUSTER'
Function: generate_pdf_report
Stack Trace:
Traceback (most recent call last):
  File "C:\Users\ravel\OneDrive\Desktop\health-check-poc-2\health-check-poc\venv\Lib\site-packages\pandas\core\indexes\base.py", line 3812, in get_loc
    return self._engine.get_loc(casted_key)
           ~~~~~~~~~~~~~~~~~~~~^^^^^^^^^^^^
  File "pandas/_libs/index.pyx", line 167, in pandas._libs.index.IndexEngine.get_loc
  File "pandas/_libs/index.pyx", line 196, in pandas._libs.index.IndexEngine.get_loc
  File "pandas/_libs/hashtable_class_helper.pxi", line 7088, in pandas._libs.hashtable.PyObjectHashTable.get_item
  File "pandas/_libs/hashtable_class_helper.pxi", line 7096, in pandas._libs.hashtable.PyObjectHashTable.get_item
KeyError: 'CLUSTER'

The above exception was the direct cause of the following exception:

Traceback (most recent call last):
  File "C:\Users\ravel\OneDrive\Desktop\health-check-poc-2\health-check-poc\health-check-v12.py", line 2945, in generate_pdf_report
    if server_row['CLUSTER'] == '1' :
       ~~~~~~~~~~^^^^^^^^^^^
  File "C:\Users\ravel\OneDrive\Desktop\health-check-poc-2\health-check-poc\venv\Lib\site-packages\pandas\core\series.py", line 1130, in __getitem__
    return self._get_value(key)
           ~~~~~~~~~~~~~~~^^^^^
  File "C:\Users\ravel\OneDrive\Desktop\health-check-poc-2\health-check-poc\venv\Lib\site-packages\pandas\core\series.py", line 1246, in _get_value
    loc = self.index.get_loc(label)
  File "C:\Users\ravel\OneDrive\Desktop\health-check-poc-2\health-check-poc\venv\Lib\site-packages\pandas\core\indexes\base.py", line 3819, in get_loc
    raise KeyError(key) from err
KeyError: 'CLUSTER'


2025-08-29 10:14:07.870531 - Error: ('28000', "[28000] [Microsoft][ODBC Driver 17 for SQL Server][SQL Server]Login failed for user 'admn0'. (18456) (SQLDriverConnect); [28000] [Microsoft][ODBC Driver 17 for SQL Server]Invalid connection string attribute (0); [28000] [Microsoft][ODBC Driver 17 for SQL Server][SQL Server]Login failed for user 'admn0'. (18456); [28000] [Microsoft][ODBC Driver 17 for SQL Server]Invalid connection string attribute (0)")
Function: Tried ODBC: {valid_driver} or failed test_connection
Stack Trace:
Traceback (most recent call last):
  File "C:\Users\ravel\OneDrive\Desktop\health-check-poc-2\health-check-poc\health-check-v12.py", line 1236, in test_connection
    self.connection = pyodbc.connect(self.conn_str, autocommit=True)
                      ~~~~~~~~~~~~~~^^^^^^^^^^^^^^^^^^^^^^^^^^^^^^^^
pyodbc.InterfaceError: ('28000', "[28000] [Microsoft][ODBC Driver 17 for SQL Server][SQL Server]Login failed for user 'admn0'. (18456) (SQLDriverConnect); [28000] [Microsoft][ODBC Driver 17 for SQL Server]Invalid connection string attribute (0); [28000] [Microsoft][ODBC Driver 17 for SQL Server][SQL Server]Login failed for user 'admn0'. (18456); [28000] [Microsoft][ODBC Driver 17 for SQL Server]Invalid connection string attribute (0)")


2025-08-29 11:18:00.034425 - Error: 'list' object has no attribute 'empty'
Function: CompatibilityLevel
Stack Trace:
Traceback (most recent call last):
  File "C:\Users\ravel\OneDrive\Desktop\health-check-poc-2\health-check-poc\health-check-v12.py", line 2035, in generate_dataframe_from_excel
    if not failed_dbs.empty() :
           ^^^^^^^^^^^^^^^^
AttributeError: 'list' object has no attribute 'empty'


